Workbook
Name CRESTA: [1]Reference!#REF!
Name General_tab: '[2]Contact information'!$D$5,'[2]Contact information'!$D$7,'[2]Contact information'!$D$9,'[2]Contact information'!$D$10,'[2]Contact information'!$D$11
Name ModellingMethod: [1]Reference!$D$3:$D$10
Name RMSVersions: [1]Reference!$E$3:$E$5
Name Syndicates: [1]Reference!$B$3:$B$89

Sheet 05 South Africa EQ Aggs
B2: South Africa Earthquake aggregate exposures
B3: Static property exposure data as at 01/01/2024 (USD units)
B5: Table 1 | H5: Table 2
B6: CRESTA zone : 2 digit | C6: Property D&F | E6: Energy | F6: Other | H6: Property Treaty | I6: Cat XL | J6: Risk XL | K6: Proportional
C7: Open Market | D7: Binding Authorities | E7: Onshore | H7: Nationwide total
B8: 00 | C8: =SUMIF('Core data'!$U$1:$U$53,'05 South Africa EQ Aggs'!B8,'Core data'!T:T) -> 24783792
B9: 01 | C9: =SUMIF('Core data'!$U$1:$U$53,'05 South Africa EQ Aggs'!B9,'Core data'!T:T) -> 0
B10: 02 | C10: =SUMIF('Core data'!$U$1:$U$53,'05 South Africa EQ Aggs'!B10,'Core data'!T:T) -> 0
B11: 03 | C11: =SUMIF('Core data'!$U$1:$U$53,'05 South Africa EQ Aggs'!B11,'Core data'!T:T) -> 0 | H11: Table 3 | I11: Aggregate Allocation %
B12: 04 | C12: =SUMIF('Core data'!$U$1:$U$53,'05 South Africa EQ Aggs'!B12,'Core data'!T:T) -> 0 | H12: Class of Business | I12: Known | J12: 'Deemed'
B13: 05 | C13: =SUMIF('Core data'!$U$1:$U$53,'05 South Africa EQ Aggs'!B13,'Core data'!T:T) -> 0 | H13: Open Market D&F
B14: 06 | C14: =SUMIF('Core data'!$U$1:$U$53,'05 South Africa EQ Aggs'!B14,'Core data'!T:T) -> 0 | H14: Binding Authorities
B15: 07 | C15: =SUMIF('Core data'!$U$1:$U$53,'05 South Africa EQ Aggs'!B15,'Core data'!T:T) -> 0 | H15: Energy (onshore)
B16: 08 | C16: =SUMIF('Core data'!$U$1:$U$53,'05 South Africa EQ Aggs'!B16,'Core data'!T:T) -> 0 | H16: Other
B17: 09 | C17: =SUMIF('Core data'!$U$1:$U$53,'05 South Africa EQ Aggs'!B17,'Core data'!T:T) -> 0 | H17: Treaty - Cat XL
B18: 10 | C18: =SUMIF('Core data'!$U$1:$U$53,'05 South Africa EQ Aggs'!B18,'Core data'!T:T) -> 0 | H18: Treaty - Risk XL
B19: 11 | C19: =SUMIF('Core data'!$U$1:$U$53,'05 South Africa EQ Aggs'!B19,'Core data'!T:T) -> 808214 | H19: Treaty - Proportional
B20: 12 | C20: =SUMIF('Core data'!$U$1:$U$53,'05 South Africa EQ Aggs'!B20,'Core data'!T:T) -> 2503591
B21: 13 | C21: =SUMIF('Core data'!$U$1:$U$53,'05 South Africa EQ Aggs'!B21,'Core data'!T:T) -> 0
B22: 14 | C22: =SUMIF('Core data'!$U$1:$U$53,'05 South Africa EQ Aggs'!B22,'Core data'!T:T) -> 0
B23: 15 | C23: =SUMIF('Core data'!$U$1:$U$53,'05 South Africa EQ Aggs'!B23,'Core data'!T:T) -> 0
B24: 16 | C24: =SUMIF('Core data'!$U$1:$U$53,'05 South Africa EQ Aggs'!B24,'Core data'!T:T) -> 0
B25: 17 | C25: =SUMIF('Core data'!$U$1:$U$53,'05 South Africa EQ Aggs'!B25,'Core data'!T:T) -> 0
B26: 18 | C26: =SUMIF('Core data'!$U$1:$U$53,'05 South Africa EQ Aggs'!B26,'Core data'!T:T) -> 0
B27: 19 | C27: =SUMIF('Core data'!$U$1:$U$53,'05 South Africa EQ Aggs'!B27,'Core data'!T:T) -> 0
B28: 20 | C28: =SUMIF('Core data'!$U$1:$U$53,'05 South Africa EQ Aggs'!B28,'Core data'!T:T) -> 2865463.3
B29: 21 | C29: =SUMIF('Core data'!$U$1:$U$53,'05 South Africa EQ Aggs'!B29,'Core data'!T:T) -> 35630813
B30: 22 | C30: =SUMIF('Core data'!$U$1:$U$53,'05 South Africa EQ Aggs'!B30,'Core data'!T:T) -> 0
B31: 23 | C31: =SUMIF('Core data'!$U$1:$U$53,'05 South Africa EQ Aggs'!B31,'Core data'!T:T) -> 0
... B102: 99 | C102: =SUMIF('Core data'!$U$1:$U$53,'05 South Africa EQ Aggs'!B102,'Core data'!T:T) -> 0

Sheet Core data
A1: PORTNAME | B1: Reclassification | C1: Countrycode | D1: COUNTRY | E1: CITY | F1: cresta | G1: COUNTY | H1: STATE | I1: latitude | J1: longitude | K1: ADDRMATCH | L1: Zone3Name | M1: ACCGRPNAME | N1: LIMITCUR | O1: TSI | P1: TSI_NET | Q1: TSI_GBP | R1: TSI_USD_NET | S1: SCALE_FACTOR | T1: scaled_tsi | U1: cresta_2_digit
A2: S33_FA_Lloyds | C2: ZA | D2: South Africa | E2: ATHOL | I2: 0 | J2: 0 | K2: 0 | M2: 1 | N2: GBP | O2: 830000 | P2: 830000 | Q2: 830000 | R2: 1118342 | S2: 1 | T2: =S2*O2 -> 830000 | U2: =IF(RIGHT(L2,2)=0,0,RIGHT(L2,2))
A3: S33_FA_Lloyds | C3: ZA | D3: South Africa | E3: SANDHURST | I3: 0 | J3: 0 | K3: 0 | M3: 1 | N3: GBP | O3: 2016802.3 | P3: 2016802.3 | Q3: 2016802.3 | R3: 2717439.4 | S3: 1 | T3: =S3*O3 -> 2016802.3 | U3: =IF(RIGHT(L3,2)=0,0,RIGHT(L3,2))
A4: S33_FA_Lloyds | C4: ZA | D4: South Africa | E4: ATHOL | I4: 0 | J4: 0 | K4: 0 | M4: 1 | N4: GBP | O4: 1406760 | P4: 1406760 | Q4: 1406760 | R4: 1895468.4 | S4: 1 | T4: =S4*O4 -> 1406760 | U4: =IF(RIGHT(L4,2)=0,0,RIGHT(L4,2))
A5: S33_FA_Lloyds | C5: ZA | D5: South Africa | E5: Cape Town | G5: City of Cape Town | H5: Western Cape | I5: -33.93457 | J5: 18.45742 | K5: 4 | L5: ZAF_79 | M5: 1 | N5: GBP | O5: 2596820.1 | P5: 2596820.1 | Q5: 2596820.1 | R5: 3498955.4 | S5: 1 | T5: =S5*O5 -> 2596820.1 | U5: =IF(RIGHT(L5,2)=0,0,RIGHT(L5,2)) -> 79
A6: S33_FA_Lloyds | C6: ZA | D6: South Africa | E6: Johannesburg | F6: 6 | G6: City of Johannesburg | H6: Gauteng | I6: -26.153081 | J6: 28.05843 | K6: 2 | L6: ZAF_21 | M6: 1 | N6: GBP | O6: 371283.94 | P6: 371283.94 | Q6: 371283.94 | R6: 500267.98 | S6: 1 | T6: =S6*O6 -> 371283.94 | U6: =IF(RIGHT(L6,2)=0,0,RIGHT(L6,2)) -> 21
A7: S33_FA_Lloyds | C7: ZA | D7: South Africa | E7: Johannesburg | G7: City of Johannesburg | H7: Gauteng | I7: -26.13822 | J7: 28.03451 | K7: 4 | L7: ZAF_21 | M7: 1 | N7: GBP | O7: 10707047 | P7: 10707047 | Q7: 10707047 | R7: 14426675 | S7: 1 | T7: =S7*O7 -> 10707047 | U7: =IF(RIGHT(L7,2)=0,0,RIGHT(L7,2)) -> 21
A8: S33_FA_Lloyds | C8: ZA | D8: South Africa | E8: Cape Town | G8: City of Cape Town | H8: Western Cape | I8: -33.90458 | J8: 18.65057 | K8: 4 | L8: ZAF_75 | M8: 1 | N8: GBP | O8: 1527253 | P8: 1527253 | Q8: 1527253 | R8: 2057820.7 | S8: 1 | T8: =S8*O8 -> 1527253 | U8: =IF(RIGHT(L8,2)=0,0,RIGHT(L8,2)) -> 75
A9: S33_FA_Lloyds | C9: ZA | D9: South Africa | E9: Port Elizabeth | G9: Nelson Mandela Bay | H9: Eastern Cape | I9: -33.954992 | J9: 25.614934 | K9: 5 | L9: ZAF_60 | M9: 1 | N9: GBP | O9: 2344789.8 | P9: 2344789.8 | Q9: 2344789.8 | R9: 3159369.8 | S9: 1 | T9: =S9*O9 -> 2344789.8 | U9: =IF(RIGHT(L9,2)=0,0,RIGHT(L9,2)) -> 60
A10: S33_FA_Lloyds | C10: ZA | D10: South Africa | E10: Cape Town | G10: Cape Winelands | H10: Western Cape | I10: -33.88989 | J10: 18.96156 | K10: 4 | L10: ZAF_76 | M10: 1 | N10: GBP | O10: 2322515.7 | P10: 2322515.7 | Q10: 2322515.7 | R10: 3129357.6 | S10: 1 | T10: =S10*O10 -> 2322515.7 | U10: =IF(RIGHT(L10,2)=0,0,RIGHT(L10,2)) -> 76
A11: S33_FA_Lloyds | C11: ZA | D11: South Africa | E11: Fish Hoek | F11: 8 | G11: City of Cape Town | H11: Western Cape | I11: -34.118959 | J11: 18.392429 | K11: 2 | L11: ZAF_79 | M11: 1 | N11: GBP | O11: 16447358 | P11: 16447358 | Q11: 16447358 | R11: 22161170 | S11: 1 | T11: =S11*O11 -> 16447358 | U11: =IF(RIGHT(L11,2)=0,0,RIGHT(L11,2)) -> 79
A12: S33_FA_Lloyds | C12: ZA | D12: South Africa | E12: Johannesburg | F12: 6 | G12: City of Johannesburg | H12: Gauteng | I12: -26.164982 | J12: 28.054421 | K12: 2 | L12: ZAF_21 | M12: 1 | N12: GBP | O12: 5276801.1 | P12: 5276801.1 | Q12: 5276801.1 | R12: 7109961.8 | S12: 1 | T12: =S12*O12 -> 5276801.1 | U12: =IF(RIGHT(L12,2)=0,0,RIGHT(L12,2)) -> 21
A13: S33_FA_Lloyds | C13: ZA | D13: South Africa | E13: CAPE TOWN | I13: 0 | J13: 0 | K13: 0 | M13: 1 | N13: GBP | O13: 6624407.3 | P13: 6624407.3 | Q13: 6624407.3 | R13: 8925726.5 | S13: 1 | T13: =S13*O13 -> 6624407.3 | U13: =IF(RIGHT(L13,2)=0,0,RIGHT(L13,2))
A14: S33_FA_Lloyds | C14: ZA | D14: South Africa | E14: PARKWOOD | I14: 0 | J14: 0 | K14: 0 | M14: 1 | N14: GBP | O14: 19699998 | P14: 19699998 | Q14: 19699998 | R14: 26543777 | S14: 1 | T14: =S14*O14 -> 19699998 | U14: =IF(RIGHT(L14,2)=0,0,RIGHT(L14,2))
A15: S33_FA_Lloyds | C15: ZA | D15: South Africa | E15: Pietermaritzburg | G15: Umgungundlovu | H15: KwaZulu-Natal | I15: -29.60238 | J15: 30.37992 | K15: 4 | L15: ZAF_32 | M15: 1 | N15: GBP | O15: 3468879.6 | P15: 3468879.6 | Q15: 3468879.6 | R15: 4673968.4 | S15: 1 | T15: =S15*O15 -> 3468879.6 | U15: =IF(RIGHT(L15,2)=0,0,RIGHT(L15,2)) -> 32
A16: S33_FA_Lloyds | C16: ZA | D16: South Africa | E16: JOHANNESBURG | I16: 0 | J16: 0 | K16: 0 | M16: 1 | N16: GBP | O16: 59133.852 | P16: 59133.852 | Q16: 59133.852 | R16: 79676.952 | S16: 1 | T16: =S16*O16 -> 59133.852 | U16: =IF(RIGHT(L16,2)=0,0,RIGHT(L16,2))
A17: S33_FA_Lloyds | C17: ZA | D17: South Africa | E17: Johannesburg | G17: City of Johannesburg | H17: Gauteng | I17: -26.18711 | J17: 28.00897 | K17: 4 | L17: ZAF_20 | M17: 1 | N17: GBP | O17: 2865463.3 | P17: 2865463.3 | Q17: 2865463.3 | R17: 3860925.3 | S17: 1 | T17: =S17*O17 -> 2865463.3 | U17: =IF(RIGHT(L17,2)=0,0,RIGHT(L17,2)) -> 20
A18: S33_FA_Lloyds | C18: ZA | D18: South Africa | E18: Cape Town | F18: 8 | G18: City of Cape Town | H18: Western Cape | I18: -33.929165 | J18: 18.377549 | K18: 2 | L18: ZAF_80 | M18: 1 | N18: GBP | O18: 5876589.7 | P18: 5876589.7 | Q18: 5876589.7 | R18: 7918117 | S18: 1 | T18: =S18*O18 -> 5876589.7 | U18: =IF(RIGHT(L18,2)=0,0,RIGHT(L18,2)) -> 80
A19: S33_FA_Lloyds | C19: ZA | D19: South Africa | E19: Sandown | F19: 6 | G19: City of Johannesburg | H19: Gauteng | I19: -26.102394 | J19: 28.059493 | K19: 2 | L19: ZAF_21 | M19: 1 | N19: GBP | O19: 3750891.6 | P19: 3750891.6 | Q19: 3750891.6 | R19: 5053951.4 | S19: 1 | T19: =S19*O19 -> 3750891.6 | U19: =IF(RIGHT(L19,2)=0,0,RIGHT(L19,2)) -> 21
A20: S33_FA_Lloyds | C20: ZA | D20: South Africa | E20: JOHANNESBURG | I20: 0 | J20: 0 | K20: 0 | M20: 1 | N20: GBP | O20: 2117722.2 | P20: 2117722.2 | Q20: 2117722.2 | R20: 2853418.9 | S20: 1 | T20: =S20*O20 -> 2117722.2 | U20: =IF(RIGHT(L20,2)=0,0,RIGHT(L20,2))
A21: S33_FA_Lloyds | C21: ZA | D21: South Africa | E21: Umhlanga | F21: 3 | G21: eThekwini | H21: KwaZulu-Natal | I21: -29.746796 | J21: 31.07476 | K21: 2 | L21: ZAF_43 | M21: 1 | N21: GBP | O21: 17080830 | P21: 17080830 | Q21: 17080830 | R21: 23014710 | S21: 1 | T21: =S21*O21 -> 17080830 | U21: =IF(RIGHT(L21,2)=0,0,RIGHT(L21,2)) -> 43
A22: S33_FA_Lloyds | C22: ZA | D22: South Africa | E22: Johannesburg | G22: City of Johannesburg | H22: Gauteng | I22: -26.17282 | J22: 28.04329 | K22: 4 | L22: ZAF_21 | M22: 1 | N22: GBP | O22: 7345930 | P22: 7345930 | Q22: 7345930 | R22: 9897906.1 | S22: 1 | T22: =S22*O22 -> 7345930 | U22: =IF(RIGHT(L22,2)=0,0,RIGHT(L22,2)) -> 21
A23: S33_FA_Lloyds | C23: ZA | D23: South Africa | E23: Cape Town | F23: 8 | G23: City of Cape Town | H23: Western Cape | I23: -33.940886 | J23: 18.406562 | K23: 2 | L23: ZAF_80 | M23: 1 | N23: GBP | O23: 850069 | P23: 850069 | Q23: 850069 | R23: 1145383 | S23: 1 | T23: =S23*O23 -> 850069 | U23: =IF(RIGHT(L23,2)=0,0,RIGHT(L23,2)) -> 80
A24: S33_FA_Lloyds | C24: ZA | D24: South Africa | E24: Johannesburg | G24: City of Johannesburg | H24: Gauteng | I24: -26.17282 | J24: 28.04329 | K24: 4 | L24: ZAF_21 | M24: 1 | N24: GBP | O24: 5517550 | P24: 5517550 | Q24: 5517550 | R24: 7434346.9 | S24: 1 | T24: =S24*O24 -> 5517550 | U24: =IF(RIGHT(L24,2)=0,0,RIGHT(L24,2)) -> 21
A25: S33_FA_Lloyds | C25: ZA | D25: South Africa | E25: Johannesburg | F25: 6 | G25: City of Johannesburg | H25: Gauteng | I25: -26.148476 | J25: 28.037118 | K25: 2 | L25: ZAF_21 | M25: 1 | N25: GBP | O25: 750000 | P25: 750000 | Q25: 750000 | R25: 1010550 | S25: 1 | T25: =S25*O25 -> 750000 | U25: =IF(RIGHT(L25,2)=0,0,RIGHT(L25,2)) -> 21
A26: S33_FA_Lloyds | C26: ZA | D26: South Africa | E26: HOUGHTON | I26: 0 | J26: 0 | K26: 0 | M26: 1 | N26: GBP | O26: 13461383 | P26: 13461383 | Q26: 13461383 | R26: 18137868 | S26: 1 | T26: =S26*O26 -> 13461383 | U26: =IF(RIGHT(L26,2)=0,0,RIGHT(L26,2))
A27: S33_FA_Lloyds | C27: ZA | D27: South Africa | E27: Piketberg | G27: West Coast | H27: Western Cape | I27: -32.78886 | J27: 18.808567 | K27: 5 | L27: ZAF_73 | M27: 1 | N27: GBP | O27: 3074321 | P27: 3074321 | Q27: 3074321 | R27: 4142340.1 | S27: 1 | T27: =S27*O27 -> 3074321 | U27: =IF(RIGHT(L27,2)=0,0,RIGHT(L27,2)) -> 73
A28: S33_FA_Lloyds | C28: ZA | D28: South Africa | E28: Belfast | G28: Nkangala | H28: Mpumalanga | I28: -25.690856 | J28: 30.035965 | K28: 5 | L28: ZAF_11 | M28: 1 | N28: GBP | O28: 808214 | P28: 808214 | Q28: 808214 | R28: 1088987.5 | S28: 1 | T28: =S28*O28 -> 808214 | U28: =IF(RIGHT(L28,2)=0,0,RIGHT(L28,2)) -> 11
A29: S33_FA_Lloyds | C29: ZA | D29: South Africa | E29: DURBAN | I29: 0 | J29: 0 | K29: 0 | M29: 1 | N29: GBP | O29: 5409576 | P29: 5409576 | Q29: 5409576 | R29: 7288862.7 | S29: 1 | T29: =S29*O29 -> 5409576 | U29: =IF(RIGHT(L29,2)=0,0,RIGHT(L29,2))
A30: S33_FA_Lloyds | C30: ZA | D30: South Africa | E30: JOHANNESBURG | I30: 0 | J30: 0 | K30: 0 | M30: 1 | N30: GBP | O30: 10819939 | P30: 10819939 | Q30: 10819939 | R30: 14578786 | S30: 1 | T30: =S30*O30 -> 10819939 | U30: =IF(RIGHT(L30,2)=0,0,RIGHT(L30,2))
A31: S33_FA_Lloyds | C31: ZA | D31: South Africa | E31: NULL | I31: 0 | J31: 0 | K31: 0 | M31: 1 | N31: GBP | O31: 9584672 | P31: 9584672 | Q31: 9584672 | R31: 12914387 | S31: 1 | T31: =S31*O31 -> 9584672 | U31: =IF(RIGHT(L31,2)=0,0,RIGHT(L31,2))
A32: S33_FA_Lloyds | C32: ZA | D32: South Africa | E32: Woodstock | F32: 8 | G32: City of Cape Town | H32: Western Cape | I32: -33.928172 | J32: 18.442952 | K32: 2 | L32: ZAF_79 | M32: 1 | N32: GBP | O32: 537379.7 | P32: 537379.7 | Q32: 537379.7 | R32: 724065.41 | S32: 1 | T32: =S32*O32 -> 537379.7 | U32: =IF(RIGHT(L32,2)=0,0,RIGHT(L32,2)) -> 79
A33: S33_FA_Lloyds | C33: ZA | D33: South Africa | E33: Pretoria | G33: City of Tshwane | H33: Gauteng | I33: -25.75638 | J33: 28.22738 | K33: 2 | L33: ZAF_00 | M33: 1 | N33: GBP | O33: 1479170.7 | P33: 1479170.7 | Q33: 1479170.7 | R33: 1993034.6 | S33: 1 | T33: =S33*O33 -> 1479170.7 | U33: =IF(RIGHT(L33,2)=0,0,RIGHT(L33,2)) -> 00
A34: S33_FA_Lloyds | C34: ZA | D34: South Africa | E34: Cape Town | G34: Cape Winelands | H34: Western Cape | I34: -33.96598 | J34: 18.84616 | K34: 4 | L34: ZAF_76 | M34: 1 | N34: GBP | O34: 7493762.1 | P34: 7493762.1 | Q34: 7493762.1 | R34: 10097095 | S34: 1 | T34: =S34*O34 -> 7493762.1 | U34: =IF(RIGHT(L34,2)=0,0,RIGHT(L34,2)) -> 76
A35: S33_FA_Lloyds | C35: ZA | D35: South Africa | E35: Kimberley | G35: Frances Baard | H35: Northern Cape | I35: -28.74368 | J35: 24.76887 | K35: 2 | L35: ZAF_83 | M35: 1 | N35: GBP | O35: 3367140.5 | P35: 3367140.5 | Q35: 3367140.5 | R35: 4536885.1 | S35: 1 | T35: =S35*O35 -> 3367140.5 | U35: =IF(RIGHT(L35,2)=0,0,RIGHT(L35,2)) -> 83
A36: S33_FA_Lloyds | C36: ZA | D36: South Africa | E36: Kimberley | G36: Frances Baard | H36: Northern Cape | I36: -28.74368 | J36: 24.76887 | K36: 2 | L36: ZAF_83 | M36: 1 | N36: GBP | O36: 1106073.8 | P36: 1106073.8 | Q36: 1106073.8 | R36: 1490323.8 | S36: 1 | T36: =S36*O36 -> 1106073.8 | U36: =IF(RIGHT(L36,2)=0,0,RIGHT(L36,2)) -> 83
A37: S33_FA_Lloyds | C37: ZA | D37: South Africa | E37: Johannesburg | G37: City of Johannesburg | H37: Gauteng | I37: -26.17097 | J37: 28.04434 | K37: 4 | L37: ZAF_21 | M37: 1 | N37: GBP | O37: 443000 | P37: 443000 | Q37: 443000 | R37: 596898.2 | S37: 1 | T37: =S37*O37 -> 443000 | U37: =IF(RIGHT(L37,2)=0,0,RIGHT(L37,2)) -> 21
A38: S33_FA_Lloyds_QS | C38: ZA | D38: South Africa | E38: NULL | I38: 0 | J38: 0 | K38: 0 | M38: 0.5 | N38: GBP | O38: 3008468.8 | P38: 1504234.4 | Q38: 3008468.8 | R38: 2026805.5 | S38: 1 | T38: =S38*O38 -> 3008468.8 | U38: =IF(RIGHT(L38,2)=0,0,RIGHT(L38,2))
A39: S33_FA_Lloyds_QS | C39: ZA | D39: South Africa | E39: Cape Town | G39: City of Cape Town | H39: Western Cape | I39: -34.07925 | J39: 18.44439 | K39: 4 | L39: ZAF_79 | M39: 0.5 | N39: GBP | O39: 808507.54 | P39: 404253.77 | Q39: 808507.54 | R39: 544691.53 | S39: 1 | T39: =S39*O39 -> 808507.54 | U39: =IF(RIGHT(L39,2)=0,0,RIGHT(L39,2)) -> 79
A40: S33_FA_Lloyds_QS | C40: ZA | D40: South Africa | E40: Cape Town | G40: City of Cape Town | H40: Western Cape | I40: -33.95411 | J40: 18.70306 | K40: 2 | L40: ZAF_75 | M40: 0.5 | N40: GBP | O40: 128478.36 | P40: 64239.178 | Q40: 128478.36 | R40: 86555.868 | S40: 1 | T40: =S40*O40 -> 128478.36 | U40: =IF(RIGHT(L40,2)=0,0,RIGHT(L40,2)) -> 75
...

Sheet Cat Class Mapping
A1: Cat Portfolio Name | B1: 7/24 to 1/25 | C1: 7/24 to 4/25 | D1: 7/24 to 7/25 | E1: 7/24 to 1/26
A2: HIC_COMM_UK | B2: 1.0996945 | C2: 1.1272121 | D2: 1.1547297 | E2: 1.2206205
A3: HIC_FA_UK | B3: 1.0122685 | C3: 1.0400845 | D3: 1.0679006 | E3: 1.1241214
A4: HIC_HH_UK | B4: 1.0122685 | C4: 1.0400845 | D4: 1.0679006 | E4: 1.1241214
A5: HIG_FA_GU | B5: 1.1417273 | C5: 1.1385381 | D5: 1.1353489 | E5: 1.1289705
A6: HIG_HH_GU | B6: 1.1417273 | C6: 1.1385381 | D6: 1.1353489 | E6: 1.1289705
A7: HSA_COMM_EU_FR | B7: 0.9676742 | C7: 0.98024496 | D7: 0.99281572 | E7: 1.0166396
A8: HSA_COMM_EU_DE | B8: 1.0468927 | C8: 1.091688 | D8: 1.1364834 | E8: 1.1975187
A9: HSA_COMM_EU_IE | B9: 1.0076253 | C9: 1.0181613 | D9: 1.0286972 | E9: 1.0520227
A10: HSA_COMM_EU_PT | B10: 0 | C10: 0 | D10: 0 | E10: 0
A11: HSA_COMM_EU_ES | B11: 0.37961138 | C11: 0.19308631 | D11: 0.0065612426 | E11: 0.0065612426
A12: HSA_COMM_UK | B12: 0.94994088 | C12: 0.95585337 | D12: 0.96176587 | E12: 0.97753252
A13: HSA_FA_EU_BE | B13: 1.0453057 | C13: 1.0538586 | D13: 1.0624115 | E13: 1.1007062
... A46: S3624_COMM_UK | B46: 0.81481481 | C46: 0.81481481 | D46: 0.81481481 | E46: 0.88888889

Sheet Notes
A1: province | B1: Cresta
A2: Gauteng | B2: 21
A3: Mpumalanga | B3: 13
A4: Western Cape | B4: 65
A5: KwaZulu-Natal | B5: 40

Sheet Fx
A2: Updated per 1/1/24 RDS instructions
A3: Currency | C3: Lloyd's Fx rate
A4: US dollars | B4: USD | C4: 1
A5: British pounds | B5: GBP | C5: 0.78740157
A6: Canadian Dollars | B6: CAD | C6: 1.3228346
A7: Euro | B7: EUR | C7: 0.90551181
A8: Australia dollar | B8: AUD | C8: 1.4724409
A9: Danish krone | B9: DKK | C9: 6.7716535
A10: Hong Kong dollar | B10: HKD | C10: 7.8346457
A11: Japanese yen | B11: JPY | C11: 141.53543
A12: New Zealand dollar | B12: NZD | C12: 1.5826772
A13: Norwegian krone | B13: NOK | C13: 10.19685
A14: Singapore dollar | B14: SGD | C14: 1.3228346
A15: South African rand | B15: ZAR | C15: 18.354331
... A17: Swiss franc | B17: CHF | C17: 0.84251969
