Workbook
Name CRESTA: [1]Reference!#REF!
Name General_tab: '[2]Contact information'!$D$5,'[2]Contact information'!$D$7,'[2]Contact information'!$D$9,'[2]Contact information'!$D$10,'[2]Contact information'!$D$11
Name ModellingMethod: [1]Reference!$D$3:$D$10
Name RMSVersions: [1]Reference!$E$3:$E$5
Name Syndicates: [1]Reference!$B$3:$B$89

Sheet 11 LIC EU CRESTA
B2: EU Aggregates by Low Res CRESTA
B3: As at 01/07/2024 (EURO units)
B5: Earthquake | F5: Flood
B6: Country | C6: CRESTA ID | D6: Aggregate | F6: Country | G6: CRESTA ID | H6: Aggregate
B7: Austria | C7: AUT_10 | D7: =SUMIFS('Core data EQ'!U:U,'Core data EQ'!L:L,'11 LIC EU CRESTA'!C7) -> 98942915 | F7: Austria | G7: AUT_10 | H7: =SUMIFS('Core data FL'!$U:$U,'Core data FL'!L:L, G7) -> 73432474
B8: Austria | C8: AUT_11 | D8: =SUMIFS('Core data EQ'!U:U,'Core data EQ'!L:L,'11 LIC EU CRESTA'!C8) -> 8572439 | F8: Austria | G8: AUT_11 | H8: =SUMIFS('Core data FL'!$U:$U,'Core data FL'!L:L, G8) -> 6362208
B9: Austria | C9: AUT_12 | D9: =SUMIFS('Core data EQ'!U:U,'Core data EQ'!L:L,'11 LIC EU CRESTA'!C9) -> 3856132.7 | F9: Austria | G9: AUT_12 | H9: =SUMIFS('Core data FL'!$U:$U,'Core data FL'!L:L, G9) -> 2861906.4
B10: Austria | C10: AUT_13 | D10: =SUMIFS('Core data EQ'!U:U,'Core data EQ'!L:L,'11 LIC EU CRESTA'!C10) -> 0 | F10: Austria | G10: AUT_13 | H10: =SUMIFS('Core data FL'!$U:$U,'Core data FL'!L:L, G10) -> 0
B11: Austria | C11: AUT_20 | D11: =SUMIFS('Core data EQ'!U:U,'Core data EQ'!L:L,'11 LIC EU CRESTA'!C11) -> 0 | F11: Austria | G11: AUT_20 | H11: =SUMIFS('Core data FL'!$U:$U,'Core data FL'!L:L, G11) -> 0
B12: Austria | C12: AUT_21 | D12: =SUMIFS('Core data EQ'!U:U,'Core data EQ'!L:L,'11 LIC EU CRESTA'!C12) -> 0 | F12: Austria | G12: AUT_21 | H12: =SUMIFS('Core data FL'!$U:$U,'Core data FL'!L:L, G12) -> 0
B13: Austria | C13: AUT_22 | D13: =SUMIFS('Core data EQ'!U:U,'Core data EQ'!L:L,'11 LIC EU CRESTA'!C13) -> 0 | F13: Austria | G13: AUT_22 | H13: =SUMIFS('Core data FL'!$U:$U,'Core data FL'!L:L, G13) -> 0
B14: Austria | C14: AUT_23 | D14: =SUMIFS('Core data EQ'!U:U,'Core data EQ'!L:L,'11 LIC EU CRESTA'!C14) -> 0 | F14: Austria | G14: AUT_23 | H14: =SUMIFS('Core data FL'!$U:$U,'Core data FL'!L:L, G14) -> 0
B15: Austria | C15: AUT_24 | D15: =SUMIFS('Core data EQ'!U:U,'Core data EQ'!L:L,'11 LIC EU CRESTA'!C15) -> 0 | F15: Austria | G15: AUT_24 | H15: =SUMIFS('Core data FL'!$U:$U,'Core data FL'!L:L, G15) -> 0
B16: Austria | C16: AUT_25 | D16: =SUMIFS('Core data EQ'!U:U,'Core data EQ'!L:L,'11 LIC EU CRESTA'!C16) -> 0 | F16: Austria | G16: AUT_25 | H16: =SUMIFS('Core data FL'!$U:$U,'Core data FL'!L:L, G16) -> 0
B17: Austria | C17: AUT_26 | D17: =SUMIFS('Core data EQ'!U:U,'Core data EQ'!L:L,'11 LIC EU CRESTA'!C17) -> 0 | F17: Austria | G17: AUT_26 | H17: =SUMIFS('Core data FL'!$U:$U,'Core data FL'!L:L, G17) -> 0
B18: Austria | C18: AUT_27 | D18: =SUMIFS('Core data EQ'!U:U,'Core data EQ'!L:L,'11 LIC EU CRESTA'!C18) -> 0 | F18: Austria | G18: AUT_27 | H18: =SUMIFS('Core data FL'!$U:$U,'Core data FL'!L:L, G18) -> 0
... B950: Switzerland | C950: CHE_ZH | D950: =SUMIFS('Core data EQ'!U:U,'Core data EQ'!L:L,'11 LIC EU CRESTA'!C950) -> 7.6169438e+08 | F950: Italy | G950: ITA_29 | H950: =SUMIFS('Core data FL'!$U:$U,'Core data FL'!L:L, G950) -> 296694.21
F951: Italy | G951: ITA_30 | H951: =SUMIFS('Core data FL'!$U:$U,'Core data FL'!L:L, G951) -> 59204204
F952: Italy | G952: ITA_31 | H952: =SUMIFS('Core data FL'!$U:$U,'Core data FL'!L:L, G952) -> 144628.1
F953: Italy | G953: ITA_32 | H953: =SUMIFS('Core data FL'!$U:$U,'Core data FL'!L:L, G953) -> 2148760.3
F954: Italy | G954: ITA_33 | H954: =SUMIFS('Core data FL'!$U:$U,'Core data FL'!L:L, G954) -> 1157355.4
F955: Italy | G955: ITA_34 | H955: =SUMIFS('Core data FL'!$U:$U,'Core data FL'!L:L, G955) -> 0
F956: Italy | G956: ITA_35 | H956: =SUMIFS('Core data FL'!$U:$U,'Core data FL'!L:L, G956) -> 8928770.6
F957: Italy | G957: ITA_36 | H957: =SUMIFS('Core data FL'!$U:$U,'Core data FL'!L:L, G957) -> 4745083.5
F958: Italy | G958: ITA_37 | H958: =SUMIFS('Core data FL'!$U:$U,'Core data FL'!L:L, G958) -> 2615702.5
F959: Italy | G959: ITA_38 | H959: =SUMIFS('Core data FL'!$U:$U,'Core data FL'!L:L, G959) -> 0
F960: Italy | G960: ITA_39 | H960: =SUMIFS('Core data FL'!$U:$U,'Core data FL'!L:L, G960) -> 4264462.8
F961: Italy | G961: ITA_40 | H961: =SUMIFS('Core data FL'!$U:$U,'Core data FL'!L:L, G961) -> 10171940
F962: Italy | G962: ITA_41 | H962: =SUMIFS('Core data FL'!$U:$U,'Core data FL'!L:L, G962) -> 661157.02
... F1885: Switzerland | G1885: CHE_ZH | H1885: =SUMIFS('Core data FL'!$U:$U,'Core data FL'!L:L, G1885) -> 5.6627464e+08

Sheet Core data FL
A1: PORTNAME | B1: Reclassification | C1: Countrycode | D1: COUNTRY | E1: CITY | F1: cresta | G1: COUNTY | H1: STATE | I1: latitude | J1: longitude | K1: ADDRMATCH | L1: Zone3Name | M1: ACCGRPNAME | N1: LIMITCUR | O1: TSI | P1: TSI_NET | Q1: TSI_GBP | R1: TSI_USD_NET | S1: Scale Factor | T1: TSI_USD_Scaled | U1: TSI_EUR_SCALED
A2: S33_FA_EU_BE | C2: CH | D2: Switzerland | E2: Grindelwald | F2: 6 | G2: Interlaken-Oberhasli | H2: Bern | I2: 46.629129 | J2: 8.018818 | K2: 1 | L2: CHE_BE | M2: 1 | N2: GBP | O2: 4210062.4 | P2: 4210062.4 | Q2: 4210062.4 | R2: 5672638.1 | S2: 1 | T2: =S2*R2 -> 5672638.1 | U2: =T2*Fx!$C$7 -> 5860163.3
A3: S33_FA_EU_BE | C3: CH | D3: Switzerland | E3: Rougemont | F3: 23 | G3: La Riviera-Pays-d'Enhaut | H3: Vaud | I3: 46.497496 | J3: 7.236686 | K3: 1 | L3: CHE_VD | M3: 1 | N3: GBP | O3: 20363.2 | P3: 20363.2 | Q3: 20363.2 | R3: 27437.376 | S3: 1 | T3: =S3*P3 -> 20363.2 | U3: =T3*Fx!$C$7 -> 21036.364
A4: S33_FA_EU_BE | C4: CH | D4: Switzerland | E4: Munchenstein | F4: 4 | G4: Arlesheim | H4: Basel-Land | I4: 47.530783 | J4: 7.610589 | K4: 1 | L4: CHE_BL | M4: 1 | N4: GBP | O4: 1685164.8 | P4: 1685164.8 | Q4: 1685164.8 | R4: 2270591.1 | S4: 1 | T4: =S4*P4 -> 1685164.8 | U4: =T4*Fx!$C$7 -> 1740872.7
A5: S33_FA_EU_BE | C5: CH | D5: Switzerland | E5: Gerignoz | F5: 23 | G5: La Riviera-Pays-d'Enhaut | H5: Vaud | I5: 46.476198 | J5: 7.138447 | K5: 1 | L5: CHE_VD | M5: 1 | N5: GBP | O5: 536592 | P5: 536592 | Q5: 536592 | R5: 723004.06 | S5: 1 | T5: =S5*P5 -> 536592 | U5: =T5*Fx!$C$7 -> 554330.58
A6: S33_FA_EU_BE | C6: CH | D6: Switzerland | E6: Kloten | F6: 25 | G6: Bulach | H6: Zurich | I6: 47.448053 | J6: 8.602014 | K6: 1 | L6: CHE_ZH | M6: 1 | N6: GBP | O6: 208000 | P6: 208000 | Q6: 208000 | R6: 280259.2 | S6: 1 | T6: =S6*P6 -> 208000 | U6: =T6*Fx!$C$7 -> 214876.03
A7: S33_FA_EU_BE | C7: CH | D7: Switzerland | E7: Les Acacias | F7: 8 | G7: Geneve | H7: Geneve | I7: 46.187685 | J7: 6.127761 | K7: 1 | L7: CHE_GE | M7: 1 | N7: GBP | O7: 4000000 | P7: 4000000 | Q7: 4000000 | R7: 5389600 | S7: 1 | T7: =S7*P7 -> 4000000 | U7: =T7*Fx!$C$7 -> 4132231.4
A8: S33_FA_EU_BE | C8: CH | D8: Switzerland | E8: Melchtal | F8: 15 | G8: Obwalden | H8: Obwalden | I8: 46.799817 | J8: 8.245024 | K8: 1 | L8: CHE_OW | M8: 1 | N8: GBP | O8: 175092.8 | P8: 175092.8 | Q8: 175092.8 | R8: 235920.04 | S8: 1 | T8: =S8*P8 -> 175092.8 | U8: =T8*Fx!$C$7 -> 180880.99
A9: S33_FA_EU_BE | C9: CH | D9: Switzerland | E9: Les Acacias | F9: 8 | G9: Geneve | H9: Geneve | I9: 46.179922 | J9: 6.133343 | K9: 1 | L9: CHE_GE | M9: 1 | N9: GBP | O9: 5220811.2 | P9: 5220811.2 | Q9: 5220811.2 | R9: 7034521 | S9: 1 | T9: =S9*P9 -> 5220811.2 | U9: =T9*Fx!$C$7 -> 5393400
A10: S33_FA_EU_BE | C10: CH | D10: Switzerland | E10: Verbier | F10: 24 | G10: Entremont | H10: Valais | I10: 46.110069 | J10: 7.228075 | K10: 1 | L10: CHE_VS | M10: 1 | N10: GBP | O10: 2616400 | P10: 2616400 | Q10: 2616400 | R10: 3525337.4 | S10: 1 | T10: =S10*P10 -> 2616400 | U10: =T10*Fx!$C$7 -> 2702892.6
A11: S33_FA_EU_BE | C11: CH | D11: Switzerland | E11: Cologny | F11: 8 | G11: Geneve | H11: Geneve | I11: 46.207943 | J11: 6.192491 | K11: 1 | L11: CHE_GE | M11: 1 | N11: GBP | O11: 99156.8 | P11: 99156.8 | Q11: 99156.8 | R11: 133603.87 | S11: 1 | T11: =S11*P11 -> 99156.8 | U11: =T11*Fx!$C$7 -> 102434.71
A12: S33_FA_EU_BE | C12: CH | D12: Switzerland | E12: Verbier | F12: 24 | G12: Entremont | H12: Valais | I12: 46.105937 | J12: 7.237815 | K12: 1 | L12: CHE_VS | M12: 1 | N12: GBP | O12: 3433699.2 | P12: 3433699.2 | Q12: 3433699.2 | R12: 4626566.3 | S12: 1 | T12: =S12*P12 -> 3433699.2 | U12: =T12*Fx!$C$7 -> 3547209.9
A13: S33_FA_EU_BE | C13: CH | D13: Switzerland | E13: Dielsdorf | F13: 25 | G13: Dielsdorf | H13: Zurich | I13: 47.485184 | J13: 8.459803 | K13: 1 | L13: CHE_ZH | M13: 1 | N13: GBP | O13: 5800000 | P13: 5800000 | Q13: 5800000 | R13: 7814920 | S13: 1 | T13: =S13*P13 -> 5800000 | U13: =T13*Fx!$C$7 -> 5991735.5
A14: S33_FA_EU_BE | C14: CH | D14: Switzerland | E14: Dielsdorf | F14: 25 | G14: Dielsdorf | H14: Zurich | I14: 47.485184 | J14: 8.459803 | K14: 1 | L14: CHE_ZH | M14: 1 | N14: GBP | O14: 11429978 | P14: 11429978 | Q14: 11429978 | R14: 15400753 | S14: 1 | T14: =S14*P14 -> 11429978 | U14: =T14*Fx!$C$7 -> 11807829
... A44: S33_FA_EU_FR | C44: FR | D44: France | E44: Paris- 16e Arrondissement | F44: 75 | G44: Paris | H44: Ile-de-France | I44: 48.862061 | J44: 2.267378 | K44: 1 | L44: FRA_75 | M44: 1 | N44: GBP | O44: 8800000 | P44: 8800000 | Q44: 8800000 | R44: 11857120 | S44: 1 | T44: =S44*P44 -> 8800000 | U44: =T44*Fx!$C$7 -> 9090909.1
A45: S33_FA_EU_FR | C45: US | D45: United States | E45: NULL | G45: NEW CASTLE COUNTY | H45: DELAWARE | I45: 39.612708 | J45: -75.760362 | K45: 1 | M45: 1 | N45: GBP | O45: 2400000 | P45: 2400000 | Q45: 2400000 | R45: 3233760 | S45: 1 | T45: =S45*P45 -> 2400000 | U45: =T45*Fx!$C$7 -> 2479338.8
A46: S33_FA_EU_FR | C46: US | D46: United States | E46: NULL | G46: QUEENS COUNTY | H46: NEW YORK | I46: 40.752235 | J46: -73.942769 | K46: 1 | M46: 1 | N46: GBP | O46: 2800000 | P46: 2800000 | Q46: 2800000 | R46: 3772720 | S46: 1 | T46: =S46*P46 -> 2800000 | U46: =T46*Fx!$C$7 -> 2892562
A47: S33_FA_EU_FR | C47: US | D47: United States | E47: NULL | G47: NEW YORK COUNTY | H47: NEW YORK | I47: 40.751337 | J47: -74.006641 | K47: 1 | M47: 1 | N47: GBP | O47: 3383154.3 | P47: 3383154.3 | Q47: 3383154.3 | R47: 4558462 | S47: 1 | T47: =S47*P47 -> 3383154.3 | U47: =T47*Fx!$C$7 -> 3494994.1
A48: S33_FA_EU_FR_QS | C48: CH | D48: Switzerland | E48: Gstaad | F48: 6 | G48: Obersimmental-Saanen | H48: Bern | I48: 46.476112 | J48: 7.288304 | K48: 1 | L48: CHE_BE | M48: 0.5 | N48: GBP | O48: 33418145 | P48: 16709072 | Q48: 33418145 | R48: 22513804 | S48: 1 | T48: =S48*P48 -> 16709072 | U48: =T48*Fx!$C$7 -> 17261438
A49: S33_FA_EU_FR_SRP | C49: CA | D49: Canada | E49: Vancouver | F49: W5 | G49: Greater Vancouver | H49: British Columbia | I49: 49.228864 | J49: -123.16521 | K49: 1 | L49: CAN_V | M49: 0.333333 | N49: GBP | O49: 3422139.3 | P49: 1140701.7 | Q49: 3422139.3 | R49: 1536981.5 | S49: 1 | T49: =S49*P49 -> 1140701.7 | U49: =T49*Fx!$C$7 -> 1178410.8
A50: S33_FA_EU_FR_SRP | C50: CA | D50: Canada | E50: Whistler | F50: 11 | G50: Squamish-Lillooet | H50: British Columbia | I50: 50.116705 | J50: -122.93985 | K50: 1 | L50: CAN_V | M50: 0.333333 | N50: GBP | O50: 843804.88 | P50: 281265.48 | Q50: 843804.88 | R50: 378977.11 | S50: 1 | T50: =S50*P50 -> 281265.48 | U50: =T50*Fx!$C$7 -> 290563.51
A51: S33_FA_EU_FR_SRP | C51: CH | D51: Switzerland | E51: Coppet | F51: 23 | G51: Nyon | H51: Vaud | I51: 46.314376 | J51: 6.190777 | K51: 1 | L51: CHE_VD | M51: 0.333333 | N51: GBP | O51: 77018791 | P51: 25672674 | Q51: 77018791 | R51: 34591360 | S51: 1 | T51: =S51*P51 -> 25672674 | U51: =T51*Fx!$C$7 -> 26521357
A52: S33_FA_EU_FR_SRP | C52: CH | D52: Switzerland | E52: Les Acacias | F52: 8 | G52: Geneve | H52: Geneve | I52: 46.18 | J52: 6.1331 | K52: 1 | L52: CHE_GE | M52: 0.333333 | N52: GBP | O52: 18630316 | P52: 6210043.4 | Q52: 18630316 | R52: 8367412.4 | S52: 1 | T52: =S52*P52 -> 6210043.4 | U52: =T52*Fx!$C$7 -> 6415334.1
A53: S33_FA_EU_FR_SRP | C53: CH | D53: Switzerland | E53: Verbier | F53: 24 | G53: Entremont | H53: Valais | I53: 46.104022 | J53: 7.237468 | K53: 1 | L53: CHE_VS | M53: 0.333333 | N53: GBP | O53: 6043114.4 | P53: 2014351.3 | Q53: 6043114.4 | R53: 2714137 | S53: 1 | T53: =S53*P53 -> 2014351.3 | U53: =T53*Fx!$C$7 -> 2080941.5
A54: S33_FA_EU_FR_SRP | C54: ID | D54: Indonesia | E54: NULL | F54: 2.3 | G54: Lahat | H54: Sumatera Selatan | I54: -3.6424971 | J54: 103.28866 | K54: 8 | L54: IDN_SS | M54: 0.333333 | N54: GBP | O54: 4287005.9 | P54: 1428987.7 | Q54: 4287005.9 | R54: 1925418 | S54: 1 | T54: =S54*P54 -> 1428987.7 | U54: =T54*Fx!$C$7 -> 1476226.9
A55: S33_FA_EU_FR_SRP | C55: SE | D55: Sweden | E55: Namdo | F55: 120 | G55: Stockholms Lan | I55: 59.177728 | J55: 18.69601 | K55: 1 | L55: SWE_0120 | M55: 0.333333 | N55: GBP | O55: 1526627.5 | P55: 508870.73 | Q55: 1526627.5 | R55: 685652.42 | S55: 1 | T55: =S55*P55 -> 508870.73 | U55: =T55*Fx!$C$7 -> 525692.9
A56: S33_FA_EU_NL | C56: CH | D56: Switzerland | E56: Geneve | F56: 8 | G56: Geneve | H56: Geneve | I56: 46.21294 | J56: 6.119039 | K56: 1 | L56: CHE_GE | M56: 1 | N56: GBP | O56: 9667000 | P56: 9667000 | Q56: 9667000 | R56: 13025316 | S56: 1 | T56: =S56*P56 -> 9667000 | U56: =T56*Fx!$C$7 -> 9986570.2
A57: S33_FA_EU_NL | C57: CH | D57: Switzerland | E57: Verbier | F57: 24 | G57: Entremont | H57: Valais | I57: 46.092552 | J57: 7.234784 | K57: 1 | L57: CHE_VS | M57: 1 | N57: GBP | O57: 557200 | P57: 557200 | Q57: 557200 | R57: 750771.28 | S57: 1 | T57: =S57*P57 -> 557200 | U57: =T57*Fx!$C$7 -> 575619.83
A58: S33_FA_EU_NL | C58: CH | D58: Switzerland | E58: Geneve | F58: 8 | G58: Geneve | H58: Geneve | I58: 46.2206 | J58: 6.149 | K58: 1 | L58: CHE_GE | M58: 1 | N58: GBP | O58: 200000 | P58: 200000 | Q58: 200000 | R58: 269480 | S58: 1 | T58: =S58*P58 -> 200000 | U58: =T58*Fx!$C$7 -> 206611.57
A59: S33_FA_EU_NL | C59: CH | D59: Switzerland | E59: Geneve | F59: 8 | G59: Geneve | H59: Geneve | I59: 46.192519 | J59: 6.150821 | K59: 1 | L59: CHE_GE | M59: 1 | N59: GBP | O59: 8380633.6 | P59: 8380633.6 | Q59: 8380633.6 | R59: 11292066 | S59: 1 | T59: =S59*P59 -> 8380633.6 | U59: =T59*Fx!$C$7 -> 8657679.3
A60: S33_FA_EU_NL | C60: SG | D60: Singapore | E60: Singapore | F60: SGP_10 | G60: Bukit Timah | H60: Central | I60: 1.321388 | J60: 103.79649 | K60: 1 | L60: SGP_10 | M60: 1 | N60: GBP | O60: 134400 | P60: 134400 | Q60: 134400 | R60: 181090.56 | S60: 1 | T60: =S60*P60 -> 134400 | U60: =T60*Fx!$C$7 -> 138842.98
A61: S33_FA_Lloyds | C61: AE | D61: United Arab Emirates | E61: Dubai | G61: Dubai | H61: Dubai | I61: 25.267406 | J61: 55.292681 | K61: 7 | M61: 1 | N61: GBP | O61: 1591634.5 | P61: 1591634.5 | Q61: 1591634.5 | R61: 2144568.3 | S61: 1 | T61: =S61*P61 -> 1591634.5 | U61: =T61*Fx!$C$7 -> 1644250.5
A62: S33_FA_Lloyds | C62: AE | D62: United Arab Emirates | E62: NULL | I62: 0 | J62: 0 | K62: 0 | M62: 1 | N62: GBP | O62: 135619.71 | P62: 135619.71 | Q62: 135619.71 | R62: 182734 | S62: 1 | T62: =S62*P62 -> 135619.71 | U62: =T62*Fx!$C$7 -> 140103.01
A63: S33_FA_Lloyds | C63: AE | D63: United Arab Emirates | E63: Dubai | G63: Dubai | H63: Dubai | I63: 25.267406 | J63: 55.292681 | K63: 7 | M63: 1 | N63: GBP | O63: 4597548.7 | P63: 4597548.7 | Q63: 4597548.7 | R63: 6194737.1 | S63: 1 | T63: =S63*P63 -> 4597548.7 | U63: =T63*Fx!$C$7 -> 4749533.8
A64: S33_FA_Lloyds | C64: AE | D64: United Arab Emirates | E64: Dubai | G64: Dubai | H64: Dubai | I64: 25.267406 | J64: 55.292681 | K64: 7 | M64: 1 | N64: GBP | O64: 9401465.1 | P64: 9401465.1 | Q64: 9401465.1 | R64: 12667534 | S64: 1 | T64: =S64*P64 -> 9401465.1 | U64: =T64*Fx!$C$7 -> 9712257.4
A65: S33_FA_Lloyds | C65: AE | D65: United Arab Emirates | E65: Dubai | G65: Dubai | H65: Dubai | I65: 25.267406 | J65: 55.292681 | K65: 7 | M65: 1 | N65: GBP | O65: 316709.04 | P65: 316709.04 | Q65: 316709.04 | R65: 426733.76 | S65: 1 | T65: =S65*P65 -> 316709.04 | U65: =T65*Fx!$C$7 -> 327178.76
A66: S33_FA_Lloyds | C66: AE | D66: United Arab Emirates | E66: Dubai | G66: Dubai | H66: Dubai | I66: 25.267406 | J66: 55.292681 | K66: 7 | M66: 1 | N66: GBP | O66: 16401 | P66: 16401 | Q66: 16401 | R66: 22098.707 | S66: 1 | T66: =S66*P66 -> 16401 | U66: =T66*Fx!$C$7 -> 16943.182
A67: S33_FA_Lloyds | C67: AE | D67: United Arab Emirates | E67: Dubai | G67: Dubai | H67: Dubai | I67: 25.267406 | J67: 55.292681 | K67: 7 | M67: 1 | N67: GBP | O67: 25000 | P67: 25000 | Q67: 25000 | R67: 33685 | S67: 1 | T67: =S67*P67 -> 25000 | U67: =T67*Fx!$C$7 -> 25826.446
A68: S33_FA_Lloyds | C68: AE | D68: United Arab Emirates | E68: Abu Dhabi | G68: Abu Dhabi | H68: Abu Dhabi | I68: 24.488176 | J68: 54.354946 | K68: 7 | M68: 1 | N68: GBP | O68: 7032115.4 | P68: 7032115.4 | Q68: 7032115.4 | R68: 9475072.3 | S68: 1 | T68: =S68*P68 -> 7032115.4 | U68: =T68*Fx!$C$7 -> 7264582
A69: S33_FA_Lloyds | C69: AE | D69: United Arab Emirates | E69: Dubai | G69: Dubai | H69: Dubai | I69: 25.267406 | J69: 55.292681 | K69: 7 | M69: 1 | N69: GBP | O69: 1050198.3 | P69: 1050198.3 | Q69: 1050198.3 | R69: 1415037.2 | S69: 1 | T69: =S69*P69 -> 1050198.3 | U69: =T69*Fx!$C$7 -> 1084915.6
...

Sheet Core data EQ
A1: PORTNAME | B1: Reclassification | C1: Countrycode | D1: COUNTRY | E1: CITY | F1: cresta | G1: COUNTY | H1: STATE | I1: latitude | J1: longitude | K1: ADDRMATCH | L1: Zone3Name | M1: ACCGRPNAME | N1: LIMITCUR | O1: TSI | P1: TSI_NET | Q1: TSI_GBP | R1: TSI_USD_NET | S1: Scale Factor | T1: TSI_USD_Scaled | U1: TSI_EUR_SCALED
A2: S33_FA_EU_BE | C2: CH | D2: Switzerland | E2: Melchtal | F2: 15 | G2: Obwalden | H2: Obwalden | I2: 46.799817 | J2: 8.245024 | K2: 1 | L2: CHE_OW | M2: 1 | N2: GBP | O2: 175092.8 | P2: 175092.8 | Q2: 175092.8 | R2: 235920.04 | S2: 1 | T2: =R2*S2 -> 235920.04 | U2: =T2*Fx!$C$7 -> 243719.05
A3: S33_FA_EU_BE | C3: CH | D3: Switzerland | E3: Les Acacias | F3: 8 | G3: Geneve | H3: Geneve | I3: 46.179922 | J3: 6.133343 | K3: 1 | L3: CHE_GE | M3: 1 | N3: GBP | O3: 5220811.2 | P3: 5220811.2 | Q3: 5220811.2 | R3: 7034521 | S3: 1 | T3: =R3*S3 -> 7034521 | U3: =T3*Fx!$C$7 -> 7267067.2
A4: S33_FA_EU_BE | C4: CH | D4: Switzerland | E4: Cologny | F4: 8 | G4: Geneve | H4: Geneve | I4: 46.207943 | J4: 6.192491 | K4: 1 | L4: CHE_GE | M4: 1 | N4: GBP | O4: 99156.8 | P4: 99156.8 | Q4: 99156.8 | R4: 133603.87 | S4: 1 | T4: =R4*S4 -> 133603.87 | U4: =T4*Fx!$C$7 -> 138020.53
A5: S33_FA_EU_BE | C5: CH | D5: Switzerland | E5: Grindelwald | F5: 6 | G5: Interlaken-Oberhasli | H5: Bern | I5: 46.629129 | J5: 8.018818 | K5: 1 | L5: CHE_BE | M5: 1 | N5: GBP | O5: 4210062.4 | P5: 4210062.4 | Q5: 4210062.4 | R5: 5672638.1 | S5: 1 | T5: =R5*S5 -> 5672638.1 | U5: =T5*Fx!$C$7 -> 5860163.3
A6: S33_FA_EU_BE | C6: CH | D6: Switzerland | E6: Dielsdorf | F6: 25 | G6: Dielsdorf | H6: Zurich | I6: 47.485184 | J6: 8.459803 | K6: 1 | L6: CHE_ZH | M6: 1 | N6: GBP | O6: 5800000 | P6: 5800000 | Q6: 5800000 | R6: 7814920 | S6: 1 | T6: =R6*S6 -> 7814920 | U6: =T6*Fx!$C$7 -> 8073264.5
A7: S33_FA_EU_BE | C7: CH | D7: Switzerland | E7: Les Acacias | F7: 8 | G7: Geneve | H7: Geneve | I7: 46.187685 | J7: 6.127761 | K7: 1 | L7: CHE_GE | M7: 1 | N7: GBP | O7: 4000000 | P7: 4000000 | Q7: 4000000 | R7: 5389600 | S7: 1 | T7: =R7*S7 -> 5389600 | U7: =T7*Fx!$C$7 -> 5567768.6
A8: S33_FA_EU_BE | C8: CH | D8: Switzerland | E8: Kloten | F8: 25 | G8: Bulach | H8: Zurich | I8: 47.448053 | J8: 8.602014 | K8: 1 | L8: CHE_ZH | M8: 1 | N8: GBP | O8: 208000 | P8: 208000 | Q8: 208000 | R8: 280259.2 | S8: 1 | T8: =R8*S8 -> 280259.2 | U8: =T8*Fx!$C$7 -> 289523.97
A9: S33_FA_EU_BE | C9: CH | D9: Switzerland | E9: Gerignoz | F9: 23 | G9: La Riviera-Pays-d'Enhaut | H9: Vaud | I9: 46.476198 | J9: 7.138447 | K9: 1 | L9: CHE_VD | M9: 1 | N9: GBP | O9: 536592 | P9: 536592 | Q9: 536592 | R9: 723004.06 | S9: 1 | T9: =R9*S9 -> 723004.06 | U9: =T9*Fx!$C$7 -> 746905.02
A10: S33_FA_EU_BE | C10: CH | D10: Switzerland | E10: Verbier | F10: 24 | G10: Entremont | H10: Valais | I10: 46.105937 | J10: 7.237815 | K10: 1 | L10: CHE_VS | M10: 1 | N10: GBP | O10: 3433699.2 | P10: 3433699.2 | Q10: 3433699.2 | R10: 4626566.3 | S10: 1 | T10: =R10*S10 -> 4626566.3 | U10: =T10*Fx!$C$7 -> 4779510.6
A11: S33_FA_EU_BE | C11: CH | D11: Switzerland | E11: Verbier | F11: 24 | G11: Entremont | H11: Valais | I11: 46.110069 | J11: 7.228075 | K11: 1 | L11: CHE_VS | M11: 1 | N11: GBP | O11: 2616400 | P11: 2616400 | Q11: 2616400 | R11: 3525337.4 | S11: 1 | T11: =R11*S11 -> 3525337.4 | U11: =T11*Fx!$C$7 -> 3641877.4
A12: S33_FA_EU_BE | C12: CH | D12: Switzerland | E12: Rougemont | F12: 23 | G12: La Riviera-Pays-d'Enhaut | H12: Vaud | I12: 46.497496 | J12: 7.236686 | K12: 1 | L12: CHE_VD | M12: 1 | N12: GBP | O12: 20363.2 | P12: 20363.2 | Q12: 20363.2 | R12: 27437.376 | S12: 1 | T12: =R12*S12 -> 27437.376 | U12: =T12*Fx!$C$7 -> 28344.396
A13: S33_FA_EU_BE | C13: CH | D13: Switzerland | E13: Dielsdorf | F13: 25 | G13: Dielsdorf | H13: Zurich | I13: 47.485184 | J13: 8.459803 | K13: 1 | L13: CHE_ZH | M13: 1 | N13: GBP | O13: 11429978 | P13: 11429978 | Q13: 11429978 | R13: 15400753 | S13: 1 | T13: =R13*S13 -> 15400753 | U13: =T13*Fx!$C$7 -> 15909869
... A44: S33_FA_EU_FR | C44: FR | D44: France | E44: Vitry-sur-Seine | F44: 94 | G44: Val-de-Marne | H44: Ile-de-France | I44: 48.801299 | J44: 2.375941 | K44: 1 | L44: FRA_94 | M44: 1 | N44: GBP | O44: 2400000 | P44: 2400000 | Q44: 2400000 | R44: 3233760 | S44: 1 | T44: =R44*S44 -> 3233760 | U44: =T44*Fx!$C$7 -> 3340661.2
A45: S33_FA_EU_FR | C45: US | D45: United States | E45: NULL | G45: NEW YORK COUNTY | H45: NEW YORK | I45: 40.751337 | J45: -74.006641 | K45: 1 | M45: 1 | N45: GBP | O45: 3383154.3 | P45: 3383154.3 | Q45: 3383154.3 | R45: 4558462 | S45: 1 | T45: =R45*S45 -> 4558462 | U45: =T45*Fx!$C$7 -> 4709155
A46: S33_FA_EU_FR | C46: US | D46: United States | E46: NULL | G46: NEW CASTLE COUNTY | H46: DELAWARE | I46: 39.612708 | J46: -75.760362 | K46: 1 | M46: 1 | N46: GBP | O46: 2400000 | P46: 2400000 | Q46: 2400000 | R46: 3233760 | S46: 1 | T46: =R46*S46 -> 3233760 | U46: =T46*Fx!$C$7 -> 3340661.2
A47: S33_FA_EU_FR | C47: US | D47: United States | E47: NULL | G47: QUEENS COUNTY | H47: NEW YORK | I47: 40.752235 | J47: -73.942769 | K47: 1 | M47: 1 | N47: GBP | O47: 2800000 | P47: 2800000 | Q47: 2800000 | R47: 3772720 | S47: 1 | T47: =R47*S47 -> 3772720 | U47: =T47*Fx!$C$7 -> 3897438
A48: S33_FA_EU_FR_QS | C48: CH | D48: Switzerland | E48: Gstaad | F48: 6 | G48: Obersimmental-Saanen | H48: Bern | I48: 46.476112 | J48: 7.288304 | K48: 1 | L48: CHE_BE | M48: 0.5 | N48: GBP | O48: 33418145 | P48: 16709072 | Q48: 33418145 | R48: 22513804 | S48: 1 | T48: =R48*S48 -> 22513804 | U48: =T48*Fx!$C$7 -> 23258062
A49: S33_FA_EU_FR_SRP | C49: CA | D49: Canada | E49: Vancouver | F49: W5 | G49: Greater Vancouver | H49: British Columbia | I49: 49.228864 | J49: -123.16521 | K49: 1 | L49: CAN_V | M49: 0.333333 | N49: GBP | O49: 3422139.3 | P49: 1140701.7 | Q49: 3422139.3 | R49: 1536981.5 | S49: 1 | T49: =R49*S49 -> 1536981.5 | U49: =T49*Fx!$C$7 -> 1587790.8
A50: S33_FA_EU_FR_SRP | C50: CA | D50: Canada | E50: Whistler | F50: 11 | G50: Squamish-Lillooet | H50: British Columbia | I50: 50.116705 | J50: -122.93985 | K50: 1 | L50: CAN_V | M50: 0.333333 | N50: GBP | O50: 843804.88 | P50: 281265.48 | Q50: 843804.88 | R50: 378977.11 | S50: 1 | T50: =R50*S50 -> 378977.11 | U50: =T50*Fx!$C$7 -> 391505.28
A51: S33_FA_EU_FR_SRP | C51: CH | D51: Switzerland | E51: Les Acacias | F51: 8 | G51: Geneve | H51: Geneve | I51: 46.18 | J51: 6.1331 | K51: 1 | L51: CHE_GE | M51: 0.333333 | N51: GBP | O51: 18630316 | P51: 6210043.4 | Q51: 18630316 | R51: 8367412.4 | S51: 1 | T51: =R51*S51 -> 8367412.4 | U51: =T51*Fx!$C$7 -> 8644021.1
A52: S33_FA_EU_FR_SRP | C52: CH | D52: Switzerland | E52: Verbier | F52: 24 | G52: Entremont | H52: Valais | I52: 46.104022 | J52: 7.237468 | K52: 1 | L52: CHE_VS | M52: 0.333333 | N52: GBP | O52: 6043114.4 | P52: 2014351.3 | Q52: 6043114.4 | R52: 2714137 | S52: 1 | T52: =R52*S52 -> 2714137 | U52: =T52*Fx!$C$7 -> 2803860.5
A53: S33_FA_EU_FR_SRP | C53: CH | D53: Switzerland | E53: Coppet | F53: 23 | G53: Nyon | H53: Vaud | I53: 46.314376 | J53: 6.190777 | K53: 1 | L53: CHE_VD | M53: 0.333333 | N53: GBP | O53: 77018791 | P53: 25672674 | Q53: 77018791 | R53: 34591360 | S53: 1 | T53: =R53*S53 -> 34591360 | U53: =T53*Fx!$C$7 -> 35734876
A54: S33_FA_EU_FR_SRP | C54: ID | D54: Indonesia | E54: NULL | F54: 2.3 | G54: Lahat | H54: Sumatera Selatan | I54: -3.6424971 | J54: 103.28866 | K54: 8 | L54: IDN_SS | M54: 0.333333 | N54: GBP | O54: 4287005.9 | P54: 1428987.7 | Q54: 4287005.9 | R54: 1925418 | S54: 1 | T54: =R54*S54 -> 1925418 | U54: =T54*Fx!$C$7 -> 1989068.2
A55: S33_FA_EU_FR_SRP | C55: SE | D55: Sweden | E55: Namdo | F55: 120 | G55: Stockholms Lan | I55: 59.177728 | J55: 18.69601 | K55: 1 | L55: SWE_0120 | M55: 0.333333 | N55: GBP | O55: 1526627.5 | P55: 508870.73 | Q55: 1526627.5 | R55: 685652.42 | S55: 1 | T55: =R55*S55 -> 685652.42 | U55: =T55*Fx!$C$7 -> 708318.61
A56: S33_FA_EU_NL | C56: CH | D56: Switzerland | E56: Verbier | F56: 24 | G56: Entremont | H56: Valais | I56: 46.092552 | J56: 7.234784 | K56: 1 | L56: CHE_VS | M56: 1 | N56: GBP | O56: 557200 | P56: 557200 | Q56: 557200 | R56: 750771.28 | S56: 1 | T56: =R56*S56 -> 750771.28 | U56: =T56*Fx!$C$7 -> 775590.17
A57: S33_FA_EU_NL | C57: CH | D57: Switzerland | E57: Geneve | F57: 8 | G57: Geneve | H57: Geneve | I57: 46.2206 | J57: 6.149 | K57: 1 | L57: CHE_GE | M57: 1 | N57: GBP | O57: 200000 | P57: 200000 | Q57: 200000 | R57: 269480 | S57: 1 | T57: =R57*S57 -> 269480 | U57: =T57*Fx!$C$7 -> 278388.43
A58: S33_FA_EU_NL | C58: CH | D58: Switzerland | E58: Geneve | F58: 8 | G58: Geneve | H58: Geneve | I58: 46.192519 | J58: 6.150821 | K58: 1 | L58: CHE_GE | M58: 1 | N58: GBP | O58: 8380633.6 | P58: 8380633.6 | Q58: 8380633.6 | R58: 11292066 | S58: 1 | T58: =R58*S58 -> 11292066 | U58: =T58*Fx!$C$7 -> 11665357
A59: S33_FA_EU_NL | C59: CH | D59: Switzerland | E59: Geneve | F59: 8 | G59: Geneve | H59: Geneve | I59: 46.21294 | J59: 6.119039 | K59: 1 | L59: CHE_GE | M59: 1 | N59: GBP | O59: 9667000 | P59: 9667000 | Q59: 9667000 | R59: 13025316 | S59: 1 | T59: =R59*S59 -> 13025316 | U59: =T59*Fx!$C$7 -> 13455905
A60: S33_FA_EU_NL | C60: SG | D60: Singapore | E60: Singapore | F60: SGP_10 | G60: Bukit Timah | H60: Central | I60: 1.321388 | J60: 103.79649 | K60: 1 | L60: SGP_10 | M60: 1 | N60: GBP | O60: 134400 | P60: 134400 | Q60: 134400 | R60: 181090.56 | S60: 1 | T60: =R60*S60 -> 181090.56 | U60: =T60*Fx!$C$7 -> 187077.02
A61: S33_FA_Lloyds | C61: AE | D61: United Arab Emirates | E61: Dubai | G61: Dubai | H61: Dubai | I61: 25.267406 | J61: 55.292681 | K61: 7 | M61: 1 | N61: GBP | O61: 316709.04 | P61: 316709.04 | Q61: 316709.04 | R61: 426733.76 | S61: 1 | T61: =R61*S61 -> 426733.76 | U61: =T61*Fx!$C$7 -> 440840.66
A62: S33_FA_Lloyds | C62: AE | D62: United Arab Emirates | E62: NULL | I62: 0 | J62: 0 | K62: 0 | M62: 1 | N62: GBP | O62: 20000 | P62: 20000 | Q62: 20000 | R62: 26948 | S62: 1 | T62: =R62*S62 -> 26948 | U62: =T62*Fx!$C$7 -> 27838.843
A63: S33_FA_Lloyds | C63: AE | D63: United Arab Emirates | E63: Dubai | G63: Dubai | H63: Dubai | I63: 25.267406 | J63: 55.292681 | K63: 7 | M63: 1 | N63: GBP | O63: 25000 | P63: 25000 | Q63: 25000 | R63: 33685 | S63: 1 | T63: =R63*S63 -> 33685 | U63: =T63*Fx!$C$7 -> 34798.554
A64: S33_FA_Lloyds | C64: AE | D64: United Arab Emirates | E64: Abu Dhabi | G64: Abu Dhabi | H64: Abu Dhabi | I64: 24.488176 | J64: 54.354946 | K64: 7 | M64: 1 | N64: GBP | O64: 7032115.4 | P64: 7032115.4 | Q64: 7032115.4 | R64: 9475072.3 | S64: 1 | T64: =R64*S64 -> 9475072.3 | U64: =T64*Fx!$C$7 -> 9788297.8
A65: S33_FA_Lloyds | C65: AE | D65: United Arab Emirates | E65: Abu Dhabi | G65: Abu Dhabi | H65: Abu Dhabi | I65: 24.488176 | J65: 54.354946 | K65: 7 | M65: 1 | N65: GBP | O65: 7605 | P65: 7605 | Q65: 7605 | R65: 10246.977 | S65: 1 | T65: =R65*S65 -> 10246.977 | U65: =T65*Fx!$C$7 -> 10585.72
A66: S33_FA_Lloyds | C66: AE | D66: United Arab Emirates | E66: Dubai | G66: Dubai | H66: Dubai | I66: 25.267406 | J66: 55.292681 | K66: 7 | M66: 1 | N66: GBP | O66: 1050198.3 | P66: 1050198.3 | Q66: 1050198.3 | R66: 1415037.2 | S66: 1 | T66: =R66*S66 -> 1415037.2 | U66: =T66*Fx!$C$7 -> 1461815.3
A67: S33_FA_Lloyds | C67: AE | D67: United Arab Emirates | E67: Dubai | G67: Dubai | H67: Dubai | I67: 25.267406 | J67: 55.292681 | K67: 7 | M67: 1 | N67: GBP | O67: 16401 | P67: 16401 | Q67: 16401 | R67: 22098.707 | S67: 1 | T67: =R67*S67 -> 22098.707 | U67: =T67*Fx!$C$7 -> 22829.243
A68: S33_FA_Lloyds | C68: AE | D68: United Arab Emirates | E68: Dubai | G68: Dubai | H68: Dubai | I68: 25.267406 | J68: 55.292681 | K68: 7 | M68: 1 | N68: GBP | O68: 42428.993 | P68: 42428.993 | Q68: 42428.993 | R68: 57168.825 | S68: 1 | T68: =R68*S68 -> 57168.825 | U68: =T68*Fx!$C$7 -> 59058.703
A69: S33_FA_Lloyds | C69: AE | D69: United Arab Emirates | E69: Dubai | G69: Dubai | H69: Dubai | I69: 25.267406 | J69: 55.292681 | K69: 7 | M69: 1 | N69: GBP | O69: 9401465.1 | P69: 9401465.1 | Q69: 9401465.1 | R69: 12667534 | S69: 1 | T69: =R69*S69 -> 12667534 | U69: =T69*Fx!$C$7 -> 13086296
A70: S33_FA_Lloyds | C70: AE | D70: United Arab Emirates | E70: Abu Dhabi | G70: Abu Dhabi | H70: Abu Dhabi | I70: 24.488176 | J70: 54.354946 | K70: 7 | M70: 1 | N70: GBP | O70: 316321.76 | P70: 316321.76 | Q70: 316321.76 | R70: 426211.94 | S70: 1 | T70: =R70*S70 -> 426211.94 | U70: =T70*Fx!$C$7 -> 440301.59
...

Sheet Cat Class Mapping
A1: Cat Portfolio Name
A2: HIC_COMM_UK
A3: HIC_FA_UK
A4: HIC_HH_UK
A5: HIG_FA_GU
A6: HIG_HH_GU
A7: HSA_COMM_EU_FR
A8: HSA_COMM_EU_DE
A9: HSA_COMM_EU_IE
A10: HSA_COMM_EU_PT
A11: HSA_COMM_EU_ES
A12: HSA_COMM_UK
... A46: S3624_COMM_UK

Sheet Notes

Sheet Fx
A2: Updated per 1/7/24 RDS instructions
A3: Currency | C3: Lloyd's Fx rate
A4: US dollars | B4: USD | C4: 1
A5: British pounds | B5: GBP | C5: 0.79365079
A6: Canadian Dollars | B6: CAD | C6: 1.3730159
A7: Euro | B7: EUR | C7: =1.25/1.21 -> 1.0330579
A18: GBP
A19: 1 | B19: 1.25 | C19: USD
A20: 1 | B20: 1.21 | C20: EUR
B21: =1.25/1.21 -> 1.0330579
